Workbook

Sheet Data Profile
A1: Data Profile – Sicily Airbnb listings (raw file Sicily.csv)
A2: One row per column of the raw file (90 columns, 56,873 rows). Missing % = Missing Count ÷ total rows (Summary!B4). Min/Max are shown for numeric and date columns; "—" means not applicable. Mean/Median and Most Frequent are static values computed with pandas.
A4: Column | B4: Data Type | C4: Logical Type | D4: Missing Count | E4: Missing % | F4: Unique Values | G4: Min | H4: Max | I4: Mean | J4: Median | K4: Most Frequent Value (count) | L4: Used in Project | M4: Notes
A5: id | B5: int64 | C5: Identifier | D5: 0 | E5: =D5/Summary!$B$4 -> 0 | F5: 56873 | G5: 7011 | H5: 1719094868989988273 | K5: — | L5: Yes | M5: Primary key. All 56,873 values are unique (no duplicate listings).
A6: listing_url | B6: object (text) | C6: URL | D6: 0 | E6: =D6/Summary!$B$4 -> 0 | F6: 56873 | G6: — | H6: — | K6: — | L6: No | M6: Link; not needed for analysis.
A7: scrape_id | B7: int64 | C7: Identifier | D7: 0 | E7: =D7/Summary!$B$4 -> 0 | F7: 1 | G7: 20260630203043 | H7: 20260630203043 | K7: 20260630203043 (56,873) | L7: No | M7: Constant value for every row: carries no information.
A8: last_scraped | B8: object (text) | C8: Date (stored as text) | D8: 0 | E8: =D8/Summary!$B$4 -> 0 | F8: 2 | G8: 2026-07-01 | H8: 2026-07-02 | K8: 2026-07-02 (31,312) | L8: No | M8: 2 scrape dates only.
A9: source | B9: object (text) | C9: Category | D9: 0 | E9: =D9/Summary!$B$4 -> 0 | F9: 2 | G9: — | H9: — | K9: city scrape (52,489) | L9: No
A10: name | B10: object (text) | C10: Free text | D10: 0 | E10: =D10/Summary!$B$4 -> 0 | F10: 54619 | G10: — | H10: — | K10: Appartamento (16) | L10: No
A11: description | B11: object (text) | C11: Free text | D11: 1297 | E11: =D11/Summary!$B$4 -> 0.022805198 | F11: 47970 | G11: — | H11: — | K11: Relax with the whole family in this qu… (380) | L11: No
A12: neighborhood_overview | B12: float64 | C12: Empty (100% missing) | D12: 56873 | E12: =D12/Summary!$B$4 -> 1 | F12: 0 | G12: — | H12: — | K12: — | L12: No | M12: Column is completely empty: no usable information.
A13: picture_url | B13: object (text) | C13: URL | D13: 18 | E13: =D13/Summary!$B$4 -> 0.00031649465 | F13: 56110 | G13: — | H13: — | K13: https://a0.muscache.com/pictures/11b0f… (10) | L13: No | M13: Link; not needed for analysis.
A14: host_id | B14: int64 | C14: Identifier | D14: 0 | E14: =D14/Summary!$B$4 -> 0 | F14: 29047 | G14: 16888 | H14: 1718922505592631218 | K14: 163663206 (261) | L14: No | M14: Host personal / identifying data; not needed for the project.
A15: host_url | B15: object (text) | C15: URL | D15: 0 | E15: =D15/Summary!$B$4 -> 0 | F15: 29047 | G15: — | H15: — | K15: https://www.airbnb.com/users/show/1636… (261) | L15: No | M15: Host personal / identifying data; not needed for the project.
A16: host_profile_id | B16: int64 | C16: Identifier | D16: 0 | E16: =D16/Summary!$B$4 -> 0 | F16: 29047 | G16: 1462506838956998124 | H16: 1718923122560484499 | K16: 1467872683076742628 (261) | L16: No | M16: Host personal / identifying data; not needed for the project.
A17: host_profile_url | B17: object (text) | C17: URL | D17: 0 | E17: =D17/Summary!$B$4 -> 0 | F17: 29047 | G17: — | H17: — | K17: https://www.airbnb.com/users/profile/1… (261) | L17: No | M17: Host personal / identifying data; not needed for the project.
A18: host_name | B18: object (text) | C18: Free text | D18: 0 | E18: =D18/Summary!$B$4 -> 0 | F18: 5677 | G18: — | H18: — | K18: Giuseppe (1,801) | L18: No | M18: Host personal / identifying data; not needed for the project.
A19: host_since | B19: float64 | C19: Empty (100% missing) | D19: 56873 | E19: =D19/Summary!$B$4 -> 1 | F19: 0 | G19: — | H19: — | K19: — | L19: No | M19: Column is completely empty: no usable information.
A20: hosts_time_as_user_years | B20: int64 | C20: Numeric (integer) | D20: 0 | E20: =D20/Summary!$B$4 -> 0 | F20: 18 | G20: 0 | H20: 17 | I20: 6.4710144 | J20: 7 | K20: 10 (5,108) | L20: No
A21: hosts_time_as_user_months | B21: int64 | C21: Numeric (integer) | D21: 0 | E21: =D21/Summary!$B$4 -> 0 | F21: 12 | G21: 0 | H21: 11 | I21: 5.2364215 | J21: 5 | K21: 11 (6,748) | L21: No
A22: hosts_time_as_host_years | B22: float64 | C22: Numeric (integer) | D22: 1 | E22: =D22/Summary!$B$4 -> 1.7583036e-05 | F22: 16 | G22: 0 | H22: 15 | I22: 5.5155788 | J22: 5 | K22: 2.0 (6,283) | L22: No
A23: hosts_time_as_host_months | B23: float64 | C23: Numeric (integer) | D23: 1 | E23: =D23/Summary!$B$4 -> 1.7583036e-05 | F23: 12 | G23: 0 | H23: 11 | I23: 4.9794978 | J23: 4 | K23: 1.0 (7,311) | L23: No
A24: host_location | B24: object (text) | C24: Free text | D24: 20663 | E24: =D24/Summary!$B$4 -> 0.36331827 | F24: 1336 | G24: — | H24: — | K24: Palermo, Italy (5,991) | L24: No | M24: Host personal / identifying data; not needed for the project.
A25: host_about | B25: object (text) | C25: Free text | D25: 34446 | E25: =D25/Summary!$B$4 -> 0.60566525 | F25: 8491 | G25: — | H25: — | K25: At Holidu, we're on a mission to make … (1,357) | L25: No | M25: Host personal / identifying data; not needed for the project.
A26: host_response_time | B26: float64 | C26: Empty (100% missing) | D26: 56873 | E26: =D26/Summary!$B$4 -> 1 | F26: 0 | G26: — | H26: — | K26: — | L26: No | M26: Column is completely empty: no usable information.
A27: host_response_rate | B27: float64 | C27: Empty (100% missing) | D27: 56873 | E27: =D27/Summary!$B$4 -> 1 | F27: 0 | G27: — | H27: — | K27: — | L27: No | M27: Column is completely empty: no usable information.
A28: host_acceptance_rate | B28: float64 | C28: Empty (100% missing) | D28: 56873 | E28: =D28/Summary!$B$4 -> 1 | F28: 0 | G28: — | H28: — | K28: — | L28: No | M28: Column is completely empty: no usable information.
A29: host_is_superhost | B29: object (text) | C29: Boolean (t/f as text) | D29: 0 | E29: =D29/Summary!$B$4 -> 0 | F29: 2 | G29: — | H29: — | K29: f (42,675) | L29: No | M29: Evaluative label about a host (t/f). Excluded: project does not profile hosts.
A30: host_thumbnail_url | B30: float64 | C30: Empty (100% missing) | D30: 56873 | E30: =D30/Summary!$B$4 -> 1 | F30: 0 | G30: — | H30: — | K30: — | L30: No | M30: Column is completely empty: no usable information.
A31: host_picture_url | B31: object (text) | C31: URL | D31: 0 | E31: =D31/Summary!$B$4 -> 0 | F31: 24919 | G31: — | H31: — | K31: https://a0.muscache.com/im/pictures/us… (261) | L31: No | M31: Host personal / identifying data; not needed for the project.
A32: host_neighbourhood | B32: float64 | C32: Empty (100% missing) | D32: 56873 | E32: =D32/Summary!$B$4 -> 1 | F32: 0 | G32: — | H32: — | K32: — | L32: No | M32: Column is completely empty: no usable information.
A33: host_listings_count | B33: int64 | C33: Numeric (integer) | D33: 0 | E33: =D33/Summary!$B$4 -> 0 | F33: 254 | G33: 1 | H33: 6243 | I33: 47.167883 | J33: 3 | K33: 1 (18,020) | L33: No
A34: host_total_listings_count | B34: float64 | C34: Empty (100% missing) | D34: 56873 | E34: =D34/Summary!$B$4 -> 1 | F34: 0 | G34: — | H34: — | K34: — | L34: No | M34: Column is completely empty: no usable information.
A35: host_verifications | B35: float64 | C35: Empty (100% missing) | D35: 56873 | E35: =D35/Summary!$B$4 -> 1 | F35: 0 | G35: — | H35: — | K35: — | L35: No | M35: Column is completely empty: no usable information.
A36: host_has_profile_pic | B36: object (text) | C36: Boolean (t/f as text) | D36: 0 | E36: =D36/Summary!$B$4 -> 0 | F36: 2 | G36: — | H36: — | K36: t (50,995) | L36: No | M36: Values t / f stored as text.
A37: host_identity_verified | B37: object (text) | C37: Boolean (t/f as text) | D37: 0 | E37: =D37/Summary!$B$4 -> 0 | F37: 2 | G37: — | H37: — | K37: t (56,192) | L37: No | M37: Values t / f stored as text.
A38: neighbourhood | B38: float64 | C38: Empty (100% missing) | D38: 56873 | E38: =D38/Summary!$B$4 -> 1 | F38: 0 | G38: — | H38: — | K38: — | L38: No | M38: Column is completely empty: no usable information.
A39: neighbourhood_cleansed | B39: object (text) | C39: Category | D39: 0 | E39: =D39/Summary!$B$4 -> 0 | F39: 372 | G39: — | H39: — | K39: Palermo (7,810) | L39: Yes | M39: 372 areas. Name "Cefal" is truncated in the source file (probably Cefalù).
A40: neighbourhood_group_cleansed | B40: float64 | C40: Empty (100% missing) | D40: 56873 | E40: =D40/Summary!$B$4 -> 1 | F40: 0 | G40: — | H40: — | K40: — | L40: No | M40: Column is completely empty: no usable information.
A41: latitude | B41: float64 | C41: Numeric (decimal) | D41: 0 | E41: =D41/Summary!$B$4 -> 0 | F41: 46845 | G41: 35.49456 | H41: 38.81024 | I41: 37.645822 | J41: 37.80874 | K41: 37.8674177 (23) | L41: Yes | M41: Range 35.49 to 38.81; consistent with Sicily and its islands (Lampedusa ≈ 35.5).
...

Sheet Summary
A1: Dataset summary
A3: Metric | B3: Value | C3: How it is obtained
A4: Total rows (listings) | B4: 56873 | C4: Input: row count of Sicily.csv (counted with pandas).
A5: Total columns | B5: =COUNTA('Data Profile'!$A$5:$A$94) -> 90 | C5: Number of rows in the Data Profile sheet.
A6: Columns used in the project | B6: =COUNTIF('Data Profile'!$L$5:$L$94,"Yes") -> 14 | C6: Column selection in the cleaning log (14 of 90).
A7: Columns completely empty (100% missing) | B7: =COUNTIF('Data Profile'!$E$5:$E$94,1) -> 13 | C7: Missing % = 100%.
A8: Columns with more than 50% missing | B8: =COUNTIF('Data Profile'!$E$5:$E$94,">0.5") -> 14 | C8: Includes the completely empty columns.
A9: Columns with 10%–50% missing | B9: =COUNTIFS('Data Profile'!$E$5:$E$94,">=0.1",'Data Profile'!$E$5:$E$94,"<=0.5") -> 15 | C9: Between 10% and 50% inclusive.
A10: Columns with no missing values | B10: =COUNTIF('Data Profile'!$E$5:$E$94,0) -> 42 | C10: Missing count = 0.
A11: Constant columns (1 unique value) | B11: =COUNTIF('Data Profile'!$F$5:$F$94,1) -> 1 | C11: Same value in every row: no information.
A12: Numeric columns (int64 + float64) | B12: =COUNTIF('Data Profile'!$B$5:$B$94,"int64")+COUNTIF('Data Profile'!$B$5:$B$94,"float64") -> 61 | C12: Data Type = int64 or float64 (includes completely empty ones, which pandas reads as float64).
A13: Text columns (object) | B13: =COUNTIF('Data Profile'!$B$5:$B$94,"object (text)") -> 29 | C13: Data Type = object (text).
A14: Total missing cells | B14: =SUM('Data Profile'!$D$5:$D$94) -> 1024141 | C14: Sum of Missing Count.
A15: Total cells | B15: =B4*B5 -> 5118570 | C15: Rows × columns.
A16: Overall missing % | B16: =B14/B15 -> 0.20008342 | C16: Missing cells ÷ total cells.
A17: Duplicate listing ids | B17: 0 | C17: Input: counted with pandas (id.duplicated().sum()).
A18: Fully duplicated rows | B18: 0 | C18: Input: counted with pandas (df.duplicated().sum()).
A19: Listings with a price | B19: 51864 | C19: Input: counted after converting price text to number.
A20: Listings without a price (missing) | B20: =B4-B19 -> 5009 | C20: Rows − listings with a price.
A21: Share of listings without a price | B21: =B20/B4 -> 0.088073427 | C21: Missing price ÷ total rows.
A22: Listings with 0 reviews | B22: 16501 | C22: Input: counted with pandas (number_of_reviews == 0).
A23: Share of listings with 0 reviews | B23: =B22/B4 -> 0.29013768
A24: Latitude range | B24: 35.49 to 38.81 | C24: Input: min/max of latitude.
A25: Longitude range | B25: 11.93 to 15.65 | C25: Input: min/max of longitude.
A26: Scrape dates (last_scraped) | B26: 2026-07-01 / 2026-07-02 | C26: Input: unique values of last_scraped.
A28: Blue = input typed from pandas results; black = formula over the Data Profile sheet.

Sheet Numeric Stats
A1: Descriptive statistics of numeric columns (non-empty, identifiers excluded)
A3: Column | B3: Count (non-missing) | C3: Mean | D3: Std | E3: Min | F3: 25% | G3: Median (50%) | H3: 75% | I3: Max
A4: hosts_time_as_user_years | B4: 56873 | C4: 6.4710144 | D4: 4.150844 | E4: 0 | F4: 3 | G4: 7 | H4: 10 | I4: 17
A5: hosts_time_as_user_months | B5: 56873 | C5: 5.2364215 | D5: 3.7876563 | E5: 0 | F5: 2 | G5: 5 | H5: 9 | I5: 11
A6: hosts_time_as_host_years | B6: 56872 | C6: 5.5155788 | D6: 4.1082874 | E6: 0 | F6: 2 | G6: 5 | H6: 9 | I6: 15
A7: hosts_time_as_host_months | B7: 56872 | C7: 4.9794978 | D7: 3.8281151 | E7: 0 | F7: 1 | G7: 4 | H7: 9 | I7: 11
A8: host_listings_count | B8: 56873 | C8: 47.167883 | D8: 182.25014 | E8: 1 | F8: 1 | G8: 3 | H8: 6 | I8: 6243
A9: latitude | B9: 56873 | C9: 37.645822 | D9: 0.5319493 | E9: 35.49456 | F9: 37.261578 | G9: 37.80874 | H9: 38.10575 | I9: 38.81024
A10: longitude | B10: 56873 | C10: 14.141749 | D10: 1.0214864 | E10: 11.928847 | F10: 13.32782 | G10: 14.5193 | H10: 15.09685 | I10: 15.65168
A11: accommodates | B11: 56873 | C11: 4.3601709 | D11: 2.339857 | E11: 1 | F11: 3 | G11: 4 | H11: 5 | I11: 16
A12: bathrooms | B12: 48026 | C12: 1.4325261 | D12: 0.94121988 | E12: 0.5 | F12: 1 | G12: 1 | H12: 2 | I12: 19
A13: bedrooms | B13: 48360 | C13: 1.8725806 | D13: 1.1596164 | E13: 0 | F13: 1 | G13: 2 | H13: 2 | I13: 22
A14: beds | B14: 50044 | C14: 2.7580529 | D14: 1.8729531 | E14: 1 | F14: 1 | G14: 2 | H14: 4 | I14: 30
A15: price_quote_total_price | B15: 51863 | C15: 1070.3012 | D15: 15139.589 | E15: 13 | F15: 160 | G15: 321 | H15: 856 | I15: 2743331
... A48: price (parsed from text) | B48: 51864 | C48: 193.844 | D48: 554.64224 | E48: 2.02 | F48: 90 | G48: 126 | H48: 194 | I48: 88494.55
A50: Static values computed with pandas describe().

Sheet Category Counts
A1: Frequency of the main categorical columns
A3: Column | B3: Value | C3: Count | D3: % of all listings
A4: room_type | B4: Entire home/apt | C4: 45363 | D4: =C4/Summary!$B$4 -> 0.79761926
A5: room_type | B5: Private room | C5: 11233 | D5: =C5/Summary!$B$4 -> 0.19751024
A6: room_type | B6: Hotel room | C6: 207 | D6: =C6/Summary!$B$4 -> 0.0036396884
A7: room_type | B7: Shared room | C7: 70 | D7: =C7/Summary!$B$4 -> 0.0012308125
A9: property_type | B9: Entire rental unit | C9: 18564 | D9: =C9/Summary!$B$4 -> 0.32641148
A10: property_type | B10: Entire home | C10: 10808 | D10: =C10/Summary!$B$4 -> 0.19003745
A11: property_type | B11: Private room in bed and breakfast | C11: 4682 | D11: =C11/Summary!$B$4 -> 0.082323774
A12: property_type | B12: Entire condo | C12: 4660 | D12: =C12/Summary!$B$4 -> 0.081936947
A13: property_type | B13: Entire villa | C13: 4627 | D13: =C13/Summary!$B$4 -> 0.081356707
A14: property_type | B14: Entire vacation home | C14: 3625 | D14: =C14/Summary!$B$4 -> 0.063738505
A15: property_type | B15: Private room in rental unit | C15: 2377 | D15: =C15/Summary!$B$4 -> 0.041794876
A16: property_type | B16: Private room in home | C16: 1222 | D16: =C16/Summary!$B$4 -> 0.02148647
... A45: last_scraped | B45: 2026-07-01 | C45: 25561 | D45: =C45/Summary!$B$4 -> 0.44943998
A47: property_type and neighbourhood_cleansed show only the 15 most frequent values (99 and 372 values in total).

Sheet Issues Found
A1: Data quality issues found while profiling
A3: # | B3: Area | C3: Finding | D3: Evidence | E3: Why it matters | F3: Suggested handling | G3: Where handled in cleaning log
A4: 1 | B4: Structure | C4: 13 columns are completely empty | D4: neighborhood_overview, host_since, host_response_time, host_response_rate, host_acceptance_rate, host_thumbnail_url, host_neighbourhood, host_total_listings_count, host_verifications, neighbourhood, neighbourhood_group_cleansed, calendar_updated, instant_bookable | E4: No information; waste space and can mislead summaries. | F4: Exclude from the working dataset. | G4: Column selection (A–C)
A5: 2 | B5: Structure | C5: 1 constant column | D5: scrape_id | E5: Same value in every row. | F5: Exclude. | G5: Column selection (C)
A6: 3 | B6: Privacy | C6: Host-identifying and host-evaluating columns | D6: host_id, host_name, host_url, host_picture_url, host_about, host_is_superhost… | E6: Personal data not needed for a price study. | F6: Exclude. | G6: Column selection (A, B)
A7: 4 | B7: Price | C7: price is stored as text with $ and commas | D7: Example: "$262.00" | E7: Cannot compute averages or compare as text. | F7: Remove $ and commas, convert to float. | G7: Step 2
A8: 5 | B8: Price | C8: 5,009 listings have no price (8.8%) | D8: Also missing: estimated_revenue_l365d (5,009) | E8: A listing without a price cannot be compared. | F8: Remove these rows. | G8: Step 3
A9: 6 | B9: Price | C9: Extreme prices | D9: max 88,494.55 USD per night, min 2.02; price per guest up to 61,161 | E9: Likely data-entry errors or special listings; distort averages. | F9: Flag with IQR rules instead of deleting. | G9: Steps 12–14
A10: 7 | B10: Bathrooms | C10: bathrooms_text is text; numeric bathrooms has many gaps | D10: bathrooms missing 8,847 vs bathrooms_text missing 63; 168 values without a number (half-baths) | E10: Need a usable number of bathrooms. | F10: Extract number from text; half-bath = 0.5. | G10: Step 4
A11: 8 | B11: Amenities | C11: amenities is one text string holding a list | D11: Example: ["Hair dryer", "Coffee maker", …] | E11: Cannot analyse directly. | F11: Parse with json.loads and count items. | G11: Step 5
A12: 9 | B12: Missing | C12: bedrooms missing in 8,513 listings (15.0%) | D12: beds missing 6,829 | E12: Many rows would be lost if removed; value cannot be inferred. | F12: Keep as NaN; exclude explicitly in size-based comparisons. | G12: Step 6
A13: 10 | B13: Reviews | C13: 16,501 listings have no rating (29.0%) | D13: Exactly the listings with 0 reviews (16,501); every listing with at least one review has a rating | E13: A missing rating means "not rated yet", not a bad rating. | F13: Keep as NaN; never fill with 0. | G13: Step 8
A14: 11 | B14: Reviews | C14: Invalid ratings | D14: 2 listings with rating 0.0 (ids 1084850, 1322855); scale is 1–5 | E14: Out-of-range values. | F14: Set to NaN. | G14: Step 7
A15: 12 | B15: Stay rules | C15: Very long minimum stays | D15: 4 listings with minimum_nights > 365 (max 1124); 1 missing | E15: Not short-term rentals; price not comparable. | F15: Add a flag column. | G15: Steps 9–10
... A19: 16 | B19: Duplicates | C19: No duplicate listings | D19: Duplicate ids: 0; fully duplicated rows: 0 | E19: Duplicates would be counted twice. | F19: No action needed. | G19: Step 1
